Workbook

Sheet DataConsolidation
A1: Month/Product | C1: Product - A | D1: Product - B | E1: Product - C | F1: Product - D
A2: Jan | C2: 6251 | D2: 6238 | E2: 6477 | F2: 6808
A3: Feb | C3: 5468 | D3: 7024 | E3: 6456 | F3: 6363
A4: Mar | C4: 6898 | D4: 5463 | E4: 6209 | F4: 6875 | P4: CTRL-F
A5: Apr | C5: 7111 | D5: 5903 | E5: 6198 | F5: 5961
A6: May | C6: 6024 | D6: 6672 | E6: 5553 | F6: 5939
A7: Jun | C7: 5911 | D7: 5830 | E7: 4988 | F7: 5478
A8: Jul | C8: 6232 | D8: 6210 | E8: 5908 | F8: 5188
A9: Aug | C9: 5696 | D9: 6091 | E9: 5272 | F9: 6585
A10: Sep | C10: 6670 | D10: 6242 | E10: 6340 | F10: 6671
A11: Oct | C11: 5501 | D11: 6979 | E11: 5021 | F11: 5262
A12: Nov | C12: 6213 | D12: 5533 | E12: 6092 | F12: 5450
A13: Dec | C13: 6991 | D13: 6940 | E13: 5746 | F13: 5437
C18: Product - A | D18: Product - B | E18: Product - C | F18: Product - D
B19: Data Consolidation | C19: =East!$D$5 -> 1860 | D19: =East!$E$5 -> 1202 | E19: =East!$F$5 -> 1371 | F19: =East!$G$5 -> 1973
B20: Data Consolidation | C20: =North!$C$5 -> 1565 | D20: =North!$D$5 -> 1548 | E20: =North!$E$5 -> 1470 | F20: =North!$F$5 -> 1693
B21: Data Consolidation | C21: =South!$B$2 -> 1409 | D21: =South!$C$2 -> 1517 | E21: =South!$D$2 -> 1745 | F21: =South!$E$2 -> 1851
B22: Data Consolidation | C22: =West!$B$2 -> 1417 | D22: =West!$C$2 -> 1971 | E22: =West!$D$2 -> 1891 | F22: =West!$E$2 -> 1291
A23: Jan | C23: =SUM(C19:C22) -> 6251 | D23: =SUM(D19:D22) -> 6238 | E23: =SUM(E19:E22) -> 6477 | F23: =SUM(F19:F22) -> 6808
B24: Data Consolidation | C24: =East!$D$6 -> 1191 | D24: =East!$E$6 -> 1811 | E24: =East!$F$6 -> 1618 | F24: =East!$G$6 -> 1289
B25: Data Consolidation | C25: =North!$C$6 -> 1135 | D25: =North!$D$6 -> 1984 | E25: =North!$E$6 -> 1352 | F25: =North!$F$6 -> 1770
B26: Data Consolidation | C26: =South!$B$3 -> 1174 | D26: =South!$C$3 -> 1245 | E26: =South!$D$3 -> 1614 | F26: =South!$E$3 -> 1537
B27: Data Consolidation | C27: =West!$B$3 -> 1968 | D27: =West!$C$3 -> 1984 | E27: =West!$D$3 -> 1872 | F27: =West!$E$3 -> 1767
A28: Feb | C28: =SUM(C24:C27) -> 5468 | D28: =SUM(D24:D27) -> 7024 | E28: =SUM(E24:E27) -> 6456 | F28: =SUM(F24:F27) -> 6363
B29: Data Consolidation | C29: =East!$D$7 -> 1890 | D29: =East!$E$7 -> 1724 | E29: =East!$F$7 -> 1088 | F29: =East!$G$7 -> 1880
B30: Data Consolidation | C30: =North!$C$7 -> 1311 | D30: =North!$D$7 -> 1185 | E30: =North!$E$7 -> 1547 | F30: =North!$F$7 -> 1152
B31: Data Consolidation | C31: =South!$B$4 -> 1770 | D31: =South!$C$4 -> 1046 | E31: =South!$D$4 -> 1703 | F31: =South!$E$4 -> 1980
B32: Data Consolidation | C32: =West!$B$4 -> 1927 | D32: =West!$C$4 -> 1508 | E32: =West!$D$4 -> 1871 | F32: =West!$E$4 -> 1863
A33: Mar | C33: =SUM(C29:C32) -> 6898 | D33: =SUM(D29:D32) -> 5463 | E33: =SUM(E29:E32) -> 6209 | F33: =SUM(F29:F32) -> 6875
B34: Data Consolidation | C34: =East!$D$8 -> 1804 | D34: =East!$E$8 -> 1732 | E34: =East!$F$8 -> 1964 | F34: =East!$G$8 -> 1541
B35: Data Consolidation | C35: =North!$C$8 -> 1897 | D35: =North!$D$8 -> 1625 | E35: =North!$E$8 -> 1866 | F35: =North!$F$8 -> 1739
B36: Data Consolidation | C36: =South!$B$5 -> 1937 | D36: =South!$C$5 -> 1326 | E36: =South!$D$5 -> 1303 | F36: =South!$E$5 -> 1252
B37: Data Consolidation | C37: =West!$B$5 -> 1473 | D37: =West!$C$5 -> 1220 | E37: =West!$D$5 -> 1065 | F37: =West!$E$5 -> 1429
A38: Apr | C38: =SUM(C34:C37) -> 7111 | D38: =SUM(D34:D37) -> 5903 | E38: =SUM(E34:E37) -> 6198 | F38: =SUM(F34:F37) -> 5961
B39: Data Consolidation | C39: =East!$D$9 -> 1913 | D39: =East!$E$9 -> 1937 | E39: =East!$F$9 -> 1613 | F39: =East!$G$9 -> 1357
B40: Data Consolidation | C40: =North!$C$9 -> 1225 | D40: =North!$D$9 -> 1352 | E40: =North!$E$9 -> 1170 | F40: =North!$F$9 -> 1752
B41: Data Consolidation | C41: =South!$B$6 -> 1526 | D41: =South!$C$6 -> 1924 | E41: =South!$D$6 -> 1186 | F41: =South!$E$6 -> 1188
B42: Data Consolidation | C42: =West!$B$6 -> 1360 | D42: =West!$C$6 -> 1459 | E42: =West!$D$6 -> 1584 | F42: =West!$E$6 -> 1642
A43: May | C43: =SUM(C39:C42) -> 6024 | D43: =SUM(D39:D42) -> 6672 | E43: =SUM(E39:E42) -> 5553 | F43: =SUM(F39:F42) -> 5939
B44: Data Consolidation | C44: =East!$D$10 -> 1016 | D44: =East!$E$10 -> 1895 | E44: =East!$F$10 -> 1229 | F44: =East!$G$10 -> 1285
...

Sheet North
B4: Month/Product | C4: Product - A | D4: Product - B | E4: Product - C | F4: Product - D
B5: Jan | C5: 1565 | D5: 1548 | E5: 1470 | F5: 1693
B6: Feb | C6: 1135 | D6: 1984 | E6: 1352 | F6: 1770
B7: Mar | C7: 1311 | D7: 1185 | E7: 1547 | F7: 1152
B8: Apr | C8: 1897 | D8: 1625 | E8: 1866 | F8: 1739
B9: May | C9: 1225 | D9: 1352 | E9: 1170 | F9: 1752
B10: Jun | C10: 1854 | D10: 1520 | E10: 1663 | F10: 1438
B11: Jul | C11: 1805 | D11: 1508 | E11: 1755 | F11: 1356
B12: Aug | C12: 1027 | D12: 1803 | E12: 1091 | F12: 1658
B13: Sep | C13: 1833 | D13: 1552 | E13: 1511 | F13: 1596
B14: Oct | C14: 1730 | D14: 1928 | E14: 1355 | F14: 1125
B15: Nov | C15: 1620 | D15: 1860 | E15: 1704 | F15: 1263
B16: Dec | C16: 1896 | D16: 1815 | E16: 1247 | F16: 1049

Sheet South
A1: Month/Product | B1: Product - A | C1: Product - B | D1: Product - C | E1: Product - D
A2: Jan | B2: 1409 | C2: 1517 | D2: 1745 | E2: 1851
A3: Feb | B3: 1174 | C3: 1245 | D3: 1614 | E3: 1537
A4: Mar | B4: 1770 | C4: 1046 | D4: 1703 | E4: 1980
A5: Apr | B5: 1937 | C5: 1326 | D5: 1303 | E5: 1252
A6: May | B6: 1526 | C6: 1924 | D6: 1186 | E6: 1188
A7: Jun | B7: 1072 | C7: 1042 | D7: 1081 | E7: 1603
A8: Jul | B8: 1813 | C8: 1417 | D8: 1344 | E8: 1696
A9: Aug | B9: 1151 | C9: 1635 | D9: 1419 | E9: 1629
A10: Sep | B10: 1323 | C10: 1940 | D10: 1912 | E10: 1784
A11: Oct | B11: 1220 | C11: 1209 | D11: 1004 | E11: 1286
A12: Nov | B12: 1084 | C12: 1094 | D12: 1131 | E12: 1616
A13: Dec | B13: 1722 | C13: 1812 | D13: 1460 | E13: 1783

Sheet East
C4: Month/Product | D4: Product - A | E4: Product - B | F4: Product - C | G4: Product - D
C5: Jan | D5: 1860 | E5: 1202 | F5: 1371 | G5: 1973
C6: Feb | D6: 1191 | E6: 1811 | F6: 1618 | G6: 1289
C7: Mar | D7: 1890 | E7: 1724 | F7: 1088 | G7: 1880
C8: Apr | D8: 1804 | E8: 1732 | F8: 1964 | G8: 1541
C9: May | D9: 1913 | E9: 1937 | F9: 1613 | G9: 1357
C10: Jun | D10: 1016 | E10: 1895 | F10: 1229 | G10: 1285
C11: Jul | D11: 1247 | E11: 1863 | F11: 1432 | G11: 1102
C12: Aug | D12: 1649 | E12: 1229 | F12: 1457 | G12: 1692
C13: Sep | D13: 1645 | E13: 1626 | F13: 1149 | G13: 1312
C14: Oct | D14: 1234 | E14: 1888 | F14: 1026 | G14: 1068
C15: Nov | D15: 1686 | E15: 1314 | F15: 1839 | G15: 1514
C16: Dec | D16: 1702 | E16: 1798 | F16: 1575 | G16: 1476

Sheet West
A1: Month/Product | B1: Product - A | C1: Product - B | D1: Product - C | E1: Product - D
A2: Jan | B2: 1417 | C2: 1971 | D2: 1891 | E2: 1291
A3: Feb | B3: 1968 | C3: 1984 | D3: 1872 | E3: 1767
A4: Mar | B4: 1927 | C4: 1508 | D4: 1871 | E4: 1863
A5: Apr | B5: 1473 | C5: 1220 | D5: 1065 | E5: 1429
A6: May | B6: 1360 | C6: 1459 | D6: 1584 | E6: 1642
A7: Jun | B7: 1969 | C7: 1373 | D7: 1015 | E7: 1152
A8: Jul | B8: 1367 | C8: 1422 | D8: 1377 | E8: 1034
A9: Aug | B9: 1869 | C9: 1424 | D9: 1305 | E9: 1606
A10: Sep | B10: 1869 | C10: 1124 | D10: 1768 | E10: 1979
A11: Oct | B11: 1317 | C11: 1954 | D11: 1636 | E11: 1783
A12: Nov | B12: 1823 | C12: 1265 | D12: 1418 | E12: 1057
A13: Dec | B13: 1671 | C13: 1515 | D13: 1464 | E13: 1129
